<?xml version="1.0" encoding="utf-8"?>
<!-- =================================================================================== -->
<!-- |    This document was autogenerated by xacro from snake.xacro                    | -->
<!-- |    EDITING THIS FILE BY HAND IS NOT RECOMMENDED                                 | -->
<!-- =================================================================================== -->
<robot name="snake">
  <link name="head">
    <visual>
      <origin rpy="0 0 0" xyz="0 0 -0.0788375"/>
      <geometry>
        <cylinder length="0.157675" radius="0.059"/>
      </geometry>
      <material name="white">
        <color rgba="1 1 1 1"/>
      </material>
    </visual>
    <collision>
      <origin rpy="0 0 0" xyz="0 0 -0.0788375"/>
      <geometry>
        <cylinder length="0.157675" radius="0.059"/>
      </geometry>
    </collision>
    <inertial>
      <origin rpy="0 0 0" xyz="0.00226 -0.0004 -0.06288"/>
      <mass value="0.904"/>
      <inertia ixx="0.002488368" ixy="0.000001090" ixz="-0.000061073" iyy="0.002530605" iyz="-0.000022575" izz="0.001592235"/>
    </inertial>
  </link>
  <link name="head__CoB"/>
  <joint name="head__CoB_joint" type="fixed">
    <parent link="head"/>
    <child link="head__CoB"/>
    <origin rpy="0 0 0" xyz="0.00002 -0.00018 -0.0523"/>
  </joint>
  <joint name="head__OUTPUT_INTERFACE" type="fixed">
    <parent link="head"/>
    <child link="radial1__INPUT_INTERFACE"/>
    <origin rpy="0 0 0" xyz="0 0 -0.157675"/>
  </joint>
  <link name="head__ballast">
    <inertial>
      <origin rpy="0 0 0" xyz="0 0 0"/>
      <mass value="0.72"/>
      <inertia ixx="0" ixy="0" ixz="0" iyy="0" iyz="0" izz="0"/>
    </inertial>
  </link>
  <joint name="head__ballast_joint" type="fixed">
    <parent link="head"/>
    <child link="head__ballast"/>
    <origin rpy="0 0 0" xyz="0 0.059 -0.078825"/>
  </joint>
  <link name="radial1__INPUT_INTERFACE">
    <visual>
      <origin rpy="0 0 0" xyz="0 0 -0.18036"/>
      <geometry>
        <cylinder length="0.36072" radius="0.059"/>
      </geometry>
      <material name="gray">
        <color rgba="0.1 0.1 0.1 1"/>
      </material>
    </visual>
    <collision>
      <origin rpy="0 0 0" xyz="0 0 -0.18036"/>
      <geometry>
        <cylinder length="0.36072" radius="0.059"/>
      </geometry>
    </collision>
    <inertial>
      <origin rpy="0 0 0" xyz="-0.00135 0.00034 -0.21941"/>
      <mass value="2.253"/>
      <inertia ixx="0.026617803" ixy="-0.000000076" ixz="0.000051954" iyy="0.026618451" iyz="-0.000358024" izz="0.002848267"/>
    </inertial>
  </link>
  <link name="radial1_propeller_h"/>
  <joint name="radial1__PROPH_JOINT" type="fixed">
    <parent link="radial1__INPUT_INTERFACE"/>
    <child link="radial1_propeller_h"/>
    <origin rpy="0 -1.57079632679 0" xyz="0 0 -0.063"/>
  </joint>
  <link name="radial1_propeller_v"/>
  <joint name="radial1__PROPV_JOINT" type="fixed">
    <parent link="radial1__INPUT_INTERFACE"/>
    <child link="radial1_propeller_v"/>
    <origin rpy="1.57079632679 0 0" xyz="0 0 -0.163"/>
  </joint>
  <joint name="radial1__OUTPUT_INTERFACE" type="fixed">
    <parent link="radial1__INPUT_INTERFACE"/>
    <child link="rotary1__INPUT_INTERFACE"/>
    <origin rpy="0 0 0" xyz="0 0 -0.36072"/>
  </joint>
  <link name="radial1__CoB"/>
  <joint name="radial1__CoB_joint" type="fixed">
    <parent link="radial1__INPUT_INTERFACE"/>
    <child link="radial1__CoB"/>
    <origin rpy="0 0 0" xyz="-0.00111 -0.00007 -0.18575"/>
  </joint>
  <link name="radial1__IMU_1"/>
  <joint name="radial1__IMU_1_joint" type="fixed">
    <parent link="radial1__INPUT_INTERFACE"/>
    <child link="radial1__IMU_1"/>
    <origin rpy="0 0 -1.57079632679" xyz="0.03479 -0.01307 -0.28966"/>
  </joint>
  <link name="radial1__IMU_2"/>
  <joint name="radial1__IMU_2_joint" type="fixed">
    <parent link="radial1__INPUT_INTERFACE"/>
    <child link="radial1__IMU_2"/>
    <origin rpy="0 0 -1.57079632679" xyz="0.03479 -0.01307 -0.31826"/>
  </joint>
  <!-- bracket -->
  <link name="rotary1__INPUT_INTERFACE">
    <visual>
      <origin rpy="0 0 0" xyz="0 0 -0.003"/>
      <geometry>
        <cylinder length="0.006" radius="0.059"/>
      </geometry>
      <material name="white">
        <color rgba="1 1 1 1"/>
      </material>
    </visual>
    <collision>
      <origin rpy="0 0 0" xyz="0 0 -0.003"/>
      <geometry>
        <cylinder length="0.006" radius="0.059"/>
      </geometry>
    </collision>
    <inertial>
      <origin rpy="0 0 0" xyz="0 0 -0.03626"/>
      <mass value="0.0785"/>
      <inertia ixx="0.000109585" ixy="0" ixz="0" iyy="0.000127397" iyz="0.000019576" izz="0.000092265"/>
    </inertial>
  </link>
  <joint name="rotary1__JOINT" type="revolute">
    <parent link="rotary1__INPUT_INTERFACE"/>
    <child link="rotary1__OUTPUT_BODY"/>
    <origin rpy="0 0 0" xyz="0 0 -0.069"/>
    <axis xyz="0 1 0"/>
    <dynamics damping="0" friction="0"/>
    <limit effort="7.0" lower="-1.57" upper="1.57" velocity="2.208932"/>
  </joint>
  <transmission name="rotary1_trans">
    <type>transmission_interface/SimpleTransmission</type>
    <joint name="rotary1__JOINT">
      <hardwareInterface>PositionJointInterface</hardwareInterface>
    </joint>
    <actuator name="rotary1__JOINT_motor">
      <hardwareInterface>PositionJointInterface</hardwareInterface>
      <mechanicalReduction>300</mechanicalReduction>
    </actuator>
  </transmission>
  <link name="rotary1__OUTPUT_BODY">
    <visual>
      <origin rpy="0 0 0" xyz="0 0 -0.033"/>
      <geometry>
        <cylinder length="0.11" radius="0.037"/>
      </geometry>
      <material name="white">
        <color rgba="1 1 1 1"/>
      </material>
    </visual>
    <collision>
      <origin rpy="0 0 0" xyz="0 0 -0.033"/>
      <geometry>
        <cylinder length="0.11" radius="0.037"/>
      </geometry>
    </collision>
    <inertial>
      <origin rpy="0 0 0" xyz="-0.005 0.00483 -0.03164"/>
      <mass value="0.817"/>
      <inertia ixx="0.001399580" ixy="-0.000001298" ixz="0.000000097" iyy="0.001538963" iyz="-0.000056533" izz="0.000646027"/>
    </inertial>
  </link>
  <joint name="rotary1__OUTPUT_INTERFACE" type="fixed">
    <parent link="rotary1__OUTPUT_BODY"/>
    <child link="buoyancy1__INPUT_INTERFACE"/>
    <origin rpy="0 0 0" xyz="0 0 -0.11"/>
  </joint>
  <link name="rotary1__input_CoB"/>
  <joint name="rotary1__input_CoB_joint" type="fixed">
    <parent link="rotary1__INPUT_INTERFACE"/>
    <child link="rotary1__input_CoB"/>
    <origin rpy="0 0 0" xyz="0 -0.00208 -0.03492"/>
  </joint>
  <link name="rotary1__output_CoB"/>
  <joint name="rotary1__output_CoB_joint" type="fixed">
    <parent link="rotary1__OUTPUT_BODY"/>
    <child link="rotary1__output_CoB"/>
    <origin rpy="0 0 0" xyz="-0.00015 0.01231 -0.03753"/>
  </joint>
  <link name="rotary1__IMU"/>
  <joint name="rotary1__IMU_joint" type="fixed">
    <parent link="rotary1__OUTPUT_BODY"/>
    <child link="rotary1__IMU"/>
    <origin rpy="1.57079632679 -1.57079632679 0" xyz="0 0 0"/>
  </joint>
  <link name="buoyancy1__INPUT_INTERFACE">
    <visual>
      <origin rpy="0 0 0" xyz="0 0 -0.11"/>
      <geometry>
        <cylinder length="0.22" radius="0.05"/>
      </geometry>
      <material name="gray">
        <color rgba="0.1 0.1 0.1 1"/>
      </material>
    </visual>
    <collision>
      <origin rpy="0 0 0" xyz="0 0 -0.11"/>
      <geometry>
        <cylinder length="0.22" radius="0.05"/>
      </geometry>
    </collision>
    <inertial>
      <origin rpy="0 0 0" xyz="0.00019 -0.00019 -0.110"/>
      <mass value="0.229"/>
      <inertia ixx="0.001464027" ixy="0.000000223" ixz="0.000002834" iyy="0.001464027" iyz="0.000002835" izz="0.000318472"/>
    </inertial>
  </link>
  <joint name="buoyancy1__OUTPUT_INTERFACE" type="fixed">
    <parent link="buoyancy1__INPUT_INTERFACE"/>
    <child link="rotary2__INPUT_INTERFACE"/>
    <origin rpy="0 0 1.57079632679" xyz="0 0 -0.22"/>
  </joint>
  <link name="buoyancy1__CoB"/>
  <joint name="buoyancy1__CoB_joint" type="fixed">
    <parent link="buoyancy1__INPUT_INTERFACE"/>
    <child link="buoyancy1__CoB"/>
    <origin rpy="0 0 0" xyz="0.00037 0.00037 -0.110"/>
  </joint>
  <!-- bracket -->
  <link name="rotary2__INPUT_INTERFACE">
    <visual>
      <origin rpy="0 0 0" xyz="0 0 -0.003"/>
      <geometry>
        <cylinder length="0.006" radius="0.059"/>
      </geometry>
      <material name="white">
        <color rgba="1 1 1 1"/>
      </material>
    </visual>
    <collision>
      <origin rpy="0 0 0" xyz="0 0 -0.003"/>
      <geometry>
        <cylinder length="0.006" radius="0.059"/>
      </geometry>
    </collision>
    <inertial>
      <origin rpy="0 0 0" xyz="0 0 -0.03626"/>
      <mass value="0.0785"/>
      <inertia ixx="0.000109585" ixy="0" ixz="0" iyy="0.000127397" iyz="0.000019576" izz="0.000092265"/>
    </inertial>
  </link>
  <joint name="rotary2__JOINT" type="revolute">
    <parent link="rotary2__INPUT_INTERFACE"/>
    <child link="rotary2__OUTPUT_BODY"/>
    <origin rpy="0 0 0" xyz="0 0 -0.069"/>
    <axis xyz="0 1 0"/>
    <dynamics damping="0" friction="0"/>
    <limit effort="7.0" lower="-1.57" upper="1.57" velocity="2.208932"/>
  </joint>
  <transmission name="rotary2_trans">
    <type>transmission_interface/SimpleTransmission</type>
    <joint name="rotary2__JOINT">
      <hardwareInterface>PositionJointInterface</hardwareInterface>
    </joint>
    <actuator name="rotary2__JOINT_motor">
      <hardwareInterface>PositionJointInterface</hardwareInterface>
      <mechanicalReduction>300</mechanicalReduction>
    </actuator>
  </transmission>
  <link name="rotary2__OUTPUT_BODY">
    <visual>
      <origin rpy="0 0 0" xyz="0 0 -0.033"/>
      <geometry>
        <cylinder length="0.11" radius="0.037"/>
      </geometry>
      <material name="white">
        <color rgba="1 1 1 1"/>
      </material>
    </visual>
    <collision>
      <origin rpy="0 0 0" xyz="0 0 -0.033"/>
      <geometry>
        <cylinder length="0.11" radius="0.037"/>
      </geometry>
    </collision>
    <inertial>
      <origin rpy="0 0 0" xyz="-0.005 0.00483 -0.03164"/>
      <mass value="0.817"/>
      <inertia ixx="0.001399580" ixy="-0.000001298" ixz="0.000000097" iyy="0.001538963" iyz="-0.000056533" izz="0.000646027"/>
    </inertial>
  </link>
  <joint name="rotary2__OUTPUT_INTERFACE" type="fixed">
    <parent link="rotary2__OUTPUT_BODY"/>
    <child link="tail__INPUT_INTERFACE"/>
    <origin rpy="0 0 -1.57079632679" xyz="0 0 -0.11"/>
  </joint>
  <link name="rotary2__input_CoB"/>
  <joint name="rotary2__input_CoB_joint" type="fixed">
    <parent link="rotary2__INPUT_INTERFACE"/>
    <child link="rotary2__input_CoB"/>
    <origin rpy="0 0 0" xyz="0 -0.00208 -0.03492"/>
  </joint>
  <link name="rotary2__output_CoB"/>
  <joint name="rotary2__output_CoB_joint" type="fixed">
    <parent link="rotary2__OUTPUT_BODY"/>
    <child link="rotary2__output_CoB"/>
    <origin rpy="0 0 0" xyz="-0.00015 0.01231 -0.03753"/>
  </joint>
  <link name="rotary2__IMU"/>
  <joint name="rotary2__IMU_joint" type="fixed">
    <parent link="rotary2__OUTPUT_BODY"/>
    <child link="rotary2__IMU"/>
    <origin rpy="1.57079632679 -1.57079632679 0" xyz="0 0 0"/>
  </joint>
  <link name="tail__INPUT_INTERFACE">
    <visual>
      <origin rpy="0 0 0" xyz="0 0 -0.3415"/>
      <geometry>
        <cylinder length="0.683" radius="0.059"/>
      </geometry>
      <material name="gray">
        <color rgba="0.1 0.1 0.1 1"/>
      </material>
    </visual>
    <collision>
      <origin rpy="0 0 0" xyz="0 0 -0.3415"/>
      <geometry>
        <cylinder length="0.683" radius="0.059"/>
      </geometry>
    </collision>
    <inertial>
      <origin rpy="0 0 0" xyz="-0.00067 0.00007 -0.30634"/>
      <mass value="3.652"/>
      <inertia ixx="0.149985389" ixy="-0.000004908" ixz="-0.000513317" iyy="0.150107175" iyz="0.000143190" izz="0.004204507"/>
    </inertial>
  </link>
  <link name="tail__CoB"/>
  <joint name="tail__CoB_joint" type="fixed">
    <parent link="tail__INPUT_INTERFACE"/>
    <child link="tail__CoB"/>
    <origin rpy="0 0 0" xyz="-0.00019 0.00001 -0.305"/>
  </joint>
  <link name="tail_rear_propeller"/>
  <joint name="tail__PROPR_JOINT" type="fixed">
    <parent link="tail__INPUT_INTERFACE"/>
    <child link="tail_rear_propeller"/>
    <origin rpy="0 0 0" xyz="0 0 -0.683"/>
  </joint>
  <link name="tail_propeller_v"/>
  <joint name="tail__PROPV_JOINT" type="fixed">
    <parent link="tail__INPUT_INTERFACE"/>
    <child link="tail_propeller_v"/>
    <origin rpy="1.57079632679 0 0" xyz="0 0 -0.211"/>
  </joint>
  <link name="tail_propeller_h"/>
  <joint name="tail__PROPH_JOINT" type="fixed">
    <parent link="tail__INPUT_INTERFACE"/>
    <child link="tail_propeller_h"/>
    <origin rpy="0 -1.57079632679 0" xyz="0 0 -0.323"/>
  </joint>
  <link name="tail__IMU_1"/>
  <joint name="tail__IMU_1_joint" type="fixed">
    <parent link="tail__INPUT_INTERFACE"/>
    <child link="tail__IMU_1"/>
    <origin rpy="3.14159265359 0 -0.785398163397" xyz="0.01536 0.03384 -0.04246"/>
  </joint>
  <link name="tail__IMU_2"/>
  <joint name="tail__IMU_2_joint" type="fixed">
    <parent link="tail__INPUT_INTERFACE"/>
    <child link="tail__IMU_2"/>
    <origin rpy="3.14159265359 0 -0.785398163397" xyz="0.01536 0.03384 -0.07106"/>
  </joint>
  <link name="tail__IMU_3"/>
  <joint name="tail__IMU_3_joint" type="fixed">
    <parent link="tail__INPUT_INTERFACE"/>
    <child link="tail__IMU_3"/>
    <origin rpy="0 0 -1.57079632679" xyz="0.03479 0.01307 -0.49729"/>
  </joint>
</robot>
