<?xml version="1.0" encoding="utf-8"?>
<!-- =================================================================================== -->
<!-- |    This document was autogenerated by xacro from snake_buoyancy.xacro           | -->
<!-- |    EDITING THIS FILE BY HAND IS NOT RECOMMENDED                                 | -->
<!-- =================================================================================== -->
<robot name="snake">
  <link name="head">
    <inertial>
      <origin rpy="0 0 0" xyz="0.00002 -0.00018 -0.0523"/>
      <mass value="1.031822219"/>
      <inertia ixx="0.002488368" ixy="0.000001090" ixz="-0.000061073" iyy="0.002530605" iyz="-0.000022575" izz="0.001592235"/>
    </inertial>
  </link>
  <joint name="head__OUTPUT_INTERFACE" type="fixed">
    <parent link="head"/>
    <child link="radial1__INPUT_INTERFACE"/>
    <origin rpy="0 0 0" xyz="0 0 -0.157675"/>
  </joint>
  <link name="radial1__INPUT_INTERFACE">
    <inertial>
      <origin rpy="0 0 0" xyz="-0.00111 -0.00007 -0.18575"/>
      <mass value="2.123734625"/>
      <inertia ixx="0.026617803" ixy="-0.000000076" ixz="0.000051954" iyy="0.026618451" iyz="-0.000358024" izz="0.002848267"/>
    </inertial>
  </link>
  <joint name="radial1__OUTPUT_INTERFACE" type="fixed">
    <parent link="radial1__INPUT_INTERFACE"/>
    <child link="rotary1__INPUT_INTERFACE"/>
    <origin rpy="0 0 0" xyz="0 0 -0.36072"/>
  </joint>
  <!-- bracket -->
  <link name="rotary1__INPUT_INTERFACE">
    <inertial>
      <origin rpy="0 0 0" xyz="0 -0.00208 -0.03492"/>
      <mass value="0.209800704"/>
      <inertia ixx="0.000109585" ixy="0" ixz="0" iyy="0.000127397" iyz="0.000019576" izz="0.000092265"/>
    </inertial>
  </link>
  <joint name="rotary1__JOINT" type="revolute">
    <parent link="rotary1__INPUT_INTERFACE"/>
    <child link="rotary1__OUTPUT_BODY"/>
    <origin rpy="0 0 0" xyz="0 0 -0.069"/>
    <axis xyz="0 1 0"/>
    <dynamics damping="0" friction="0"/>
    <limit effort="7.0" lower="-1.57" upper="1.57" velocity="2.208932"/>
  </joint>
  <transmission name="rotary1_trans">
    <type>transmission_interface/SimpleTransmission</type>
    <joint name="rotary1__JOINT">
      <hardwareInterface>PositionJointInterface</hardwareInterface>
    </joint>
    <actuator name="rotary1__JOINT_motor">
      <hardwareInterface>PositionJointInterface</hardwareInterface>
      <mechanicalReduction>300</mechanicalReduction>
    </actuator>
  </transmission>
  <link name="rotary1__OUTPUT_BODY">
    <inertial>
      <origin rpy="0 0 0" xyz="-0.00015 0.01231 -0.03753"/>
      <mass value="0.702056493"/>
      <inertia ixx="0.001399580" ixy="-0.000001298" ixz="0.000000097" iyy="0.001538963" iyz="-0.000056533" izz="0.000646027"/>
    </inertial>
  </link>
  <joint name="rotary1__OUTPUT_INTERFACE" type="fixed">
    <parent link="rotary1__OUTPUT_BODY"/>
    <child link="buoyancy1__INPUT_INTERFACE"/>
    <origin rpy="0 0 0" xyz="0 0 -0.11"/>
  </joint>
  <link name="buoyancy1__INPUT_INTERFACE">
    <inertial>
      <origin rpy="0 0 0" xyz="0.00037 0.00037 -0.110"/>
      <mass value="1.743956388"/>
      <inertia ixx="0.001464027" ixy="0.000000223" ixz="0.000002834" iyy="0.001464027" iyz="0.000002835" izz="0.000318472"/>
    </inertial>
  </link>
  <joint name="buoyancy1__OUTPUT_INTERFACE" type="fixed">
    <parent link="buoyancy1__INPUT_INTERFACE"/>
    <child link="rotary2__INPUT_INTERFACE"/>
    <origin rpy="0 0 1.57079632679" xyz="0 0 -0.22"/>
  </joint>
  <!-- bracket -->
  <link name="rotary2__INPUT_INTERFACE">
    <inertial>
      <origin rpy="0 0 0" xyz="0 -0.00208 -0.03492"/>
      <mass value="0.209800704"/>
      <inertia ixx="0.000109585" ixy="0" ixz="0" iyy="0.000127397" iyz="0.000019576" izz="0.000092265"/>
    </inertial>
  </link>
  <joint name="rotary2__JOINT" type="revolute">
    <parent link="rotary2__INPUT_INTERFACE"/>
    <child link="rotary2__OUTPUT_BODY"/>
    <origin rpy="0 0 0" xyz="0 0 -0.069"/>
    <axis xyz="0 1 0"/>
    <dynamics damping="0" friction="0"/>
    <limit effort="7.0" lower="-1.57" upper="1.57" velocity="2.208932"/>
  </joint>
  <transmission name="rotary2_trans">
    <type>transmission_interface/SimpleTransmission</type>
    <joint name="rotary2__JOINT">
      <hardwareInterface>PositionJointInterface</hardwareInterface>
    </joint>
    <actuator name="rotary2__JOINT_motor">
      <hardwareInterface>PositionJointInterface</hardwareInterface>
      <mechanicalReduction>300</mechanicalReduction>
    </actuator>
  </transmission>
  <link name="rotary2__OUTPUT_BODY">
    <inertial>
      <origin rpy="0 0 0" xyz="-0.00015 0.01231 -0.03753"/>
      <mass value="0.702056493"/>
      <inertia ixx="0.001399580" ixy="-0.000001298" ixz="0.000000097" iyy="0.001538963" iyz="-0.000056533" izz="0.000646027"/>
    </inertial>
  </link>
  <joint name="rotary2__OUTPUT_INTERFACE" type="fixed">
    <parent link="rotary2__OUTPUT_BODY"/>
    <child link="tail__INPUT_INTERFACE"/>
    <origin rpy="0 0 -1.57079632679" xyz="0 0 -0.11"/>
  </joint>
  <link name="tail__INPUT_INTERFACE">
    <inertial>
      <origin rpy="0 0 0" xyz="-0.00019 0.00001 -0.305"/>
      <mass value="3.020276905"/>
      <inertia ixx="0.149985389" ixy="-0.000004908" ixz="-0.000513317" iyy="0.150107175" iyz="0.000143190" izz="0.004204507"/>
    </inertial>
  </link>
</robot>
